
/usr/local/lib/python3.10/dist-packages/pytorch_lightning/loggers/wandb.py:389: There is a wandb run already in progress and newly created instances of `WandbLogger` will reuse this run. If this is not desired, call `wandb.finish()` before instantiating `WandbLogger`.
GPU available: True (cuda), used: True
TPU available: False, using: 0 TPU cores
IPU available: False, using: 0 IPUs
HPU available: False, using: 0 HPUs
LOCAL_RANK: 0 - CUDA_VISIBLE_DEVICES: [0]
Error executing job with overrides: []
Traceback (most recent call last):
  File "/content/drive/MyDrive/murata_labo_exp/murata_labo_exp_src/exp5/main.py", line 638, in main
    trainer.fit(model, data_module)
  File "/usr/local/lib/python3.10/dist-packages/pytorch_lightning/trainer/trainer.py", line 544, in fit
    call._call_and_handle_interrupt(
  File "/usr/local/lib/python3.10/dist-packages/pytorch_lightning/trainer/call.py", line 44, in _call_and_handle_interrupt
    return trainer_fn(*args, **kwargs)
  File "/usr/local/lib/python3.10/dist-packages/pytorch_lightning/trainer/trainer.py", line 580, in _fit_impl
    self._run(model, ckpt_path=ckpt_path)
  File "/usr/local/lib/python3.10/dist-packages/pytorch_lightning/trainer/trainer.py", line 989, in _run
    results = self._run_stage()
  File "/usr/local/lib/python3.10/dist-packages/pytorch_lightning/trainer/trainer.py", line 1033, in _run_stage
    self._run_sanity_check()
  File "/usr/local/lib/python3.10/dist-packages/pytorch_lightning/trainer/trainer.py", line 1062, in _run_sanity_check
    val_loop.run()
  File "/usr/local/lib/python3.10/dist-packages/pytorch_lightning/loops/utilities.py", line 182, in _decorator
    return loop_run(self, *args, **kwargs)
  File "/usr/local/lib/python3.10/dist-packages/pytorch_lightning/loops/evaluation_loop.py", line 127, in run
    batch, batch_idx, dataloader_idx = next(data_fetcher)
  File "/usr/local/lib/python3.10/dist-packages/pytorch_lightning/loops/fetchers.py", line 127, in __next__
    batch = super().__next__()
  File "/usr/local/lib/python3.10/dist-packages/pytorch_lightning/loops/fetchers.py", line 56, in __next__
    batch = next(self.iterator)
  File "/usr/local/lib/python3.10/dist-packages/pytorch_lightning/utilities/combined_loader.py", line 326, in __next__
    out = next(self._iterator)
  File "/usr/local/lib/python3.10/dist-packages/pytorch_lightning/utilities/combined_loader.py", line 132, in __next__
    out = next(self.iterators[0])
  File "/usr/local/lib/python3.10/dist-packages/torch/utils/data/dataloader.py", line 630, in __next__
    data = self._next_data()
  File "/usr/local/lib/python3.10/dist-packages/torch/utils/data/dataloader.py", line 1345, in _next_data
    return self._process_data(data)
  File "/usr/local/lib/python3.10/dist-packages/torch/utils/data/dataloader.py", line 1371, in _process_data
    data.reraise()
  File "/usr/local/lib/python3.10/dist-packages/torch/_utils.py", line 694, in reraise
    raise exception
KeyError: Caught KeyError in DataLoader worker process 0.
Original Traceback (most recent call last):
  File "/usr/local/lib/python3.10/dist-packages/pandas/core/indexes/base.py", line 3802, in get_loc
    return self._engine.get_loc(casted_key)
  File "pandas/_libs/index.pyx", line 138, in pandas._libs.index.IndexEngine.get_loc
  File "pandas/_libs/index.pyx", line 165, in pandas._libs.index.IndexEngine.get_loc
  File "pandas/_libs/hashtable_class_helper.pxi", line 5745, in pandas._libs.hashtable.PyObjectHashTable.get_item
  File "pandas/_libs/hashtable_class_helper.pxi", line 5753, in pandas._libs.hashtable.PyObjectHashTable.get_item
KeyError: 'sentence'
The above exception was the direct cause of the following exception:
Traceback (most recent call last):
  File "/usr/local/lib/python3.10/dist-packages/torch/utils/data/_utils/worker.py", line 308, in _worker_loop
    data = fetcher.fetch(index)
  File "/usr/local/lib/python3.10/dist-packages/torch/utils/data/_utils/fetch.py", line 51, in fetch
    data = [self.dataset[idx] for idx in possibly_batched_index]
  File "/usr/local/lib/python3.10/dist-packages/torch/utils/data/_utils/fetch.py", line 51, in <listcomp>
    data = [self.dataset[idx] for idx in possibly_batched_index]
  File "/content/drive/MyDrive/murata_labo_exp/murata_labo_exp_src/exp5/main.py", line 38, in __getitem__
    text = data_row[self.TEXT_COLUMN]  # 行数分のtextを取得
  File "/usr/local/lib/python3.10/dist-packages/pandas/core/series.py", line 981, in __getitem__
    return self._get_value(key)
  File "/usr/local/lib/python3.10/dist-packages/pandas/core/series.py", line 1089, in _get_value
    loc = self.index.get_loc(label)
  File "/usr/local/lib/python3.10/dist-packages/pandas/core/indexes/base.py", line 3804, in get_loc
    raise KeyError(key) from err
KeyError: 'sentence'
Set the environment variable HYDRA_FULL_ERROR=1 for a complete stack trace.
┏━━━━┳━━━━━━━━━━━━━━━━━━━━━━━━━━━━━┳━━━━━━━━━━━━━━━━━━┳━━━━━━━━┓
┃[1m    [22m┃[1m Name                        [22m┃[1m Type             [22m┃[1m Params [22m┃
┡━━━━╇━━━━━━━━━━━━━━━━━━━━━━━━━━━━━╇━━━━━━━━━━━━━━━━━━╇━━━━━━━━┩
│ 0  │ bert                        │ BertModel        │ 89.1 M │
│ 1  │ classifiers                 │ ModuleList       │  6.3 M │
│ 2  │ hidden_layer1               │ ModuleList       │  2.1 M │
│ 3  │ hidden_layer2               │ ModuleList       │  2.1 K │
│ 4  │ sigmoid                     │ Sigmoid          │      0 │
│ 5  │ criterion                   │ Focal_Loss       │      0 │
│ 6  │ metrics                     │ MetricCollection │      0 │
│ 7  │ metrics_per_label_accuracy  │ MetricCollection │      0 │
│ 8  │ metrics_per_label_precision │ MetricCollection │      0 │
│ 9  │ metrics_per_label_recall    │ MetricCollection │      0 │
│ 10 │ metrics_per_label_f1score   │ MetricCollection │      0 │
└────┴─────────────────────────────┴──────────────────┴────────┘
[1mTrainable params[22m: 15.5 M
[1mNon-trainable params[22m: 82.0 M
[1mTotal params[22m: 97.5 M
[1mTotal estimated model params size (MB)[22m: 390
[?25h