The tokenizer class you load from this checkpoint is not the same type as the class this function is called from. It may result in unexpected tokenization.
The tokenizer class you load from this checkpoint is 'BertJapaneseTokenizer'.
The class this function is called from is 'BertTokenizer'.
Some weights of the model checkpoint at cl-tohoku/bert-base-japanese-whole-word-masking were not used when initializing BertModel: ['cls.seq_relationship.weight', 'cls.seq_relationship.bias', 'cls.predictions.transform.dense.weight', 'cls.predictions.transform.dense.bias', 'cls.predictions.transform.LayerNorm.weight', 'cls.predictions.decoder.weight', 'cls.predictions.bias', 'cls.predictions.transform.LayerNorm.bias']
- This IS expected if you are initializing BertModel from the checkpoint of a model trained on another task or with another architecture (e.g. initializing a BertForSequenceClassification model from a BertForPreTraining model).
- This IS NOT expected if you are initializing BertModel from the checkpoint of a model that you expect to be exactly identical (initializing a BertForSequenceClassification model from a BertForSequenceClassification model).
GPU available: True (cuda), used: True
TPU available: False, using: 0 TPU cores
IPU available: False, using: 0 IPUs
HPU available: False, using: 0 HPUs
LOCAL_RANK: 0 - CUDA_VISIBLE_DEVICES: [0]
  | Name       | Type             | Params
------------------------------------------------
0 | bert       | BertModel        | 110 M
1 | classifier | Linear           | 6.9 K
2 | criterion  | CrossEntropyLoss | 0
------------------------------------------------
7.1 M     Trainable params
103 M     Non-trainable params
110 M     Total params
442.497   Total estimated model params size (MB)
Sanity Checking DataLoader 0:   0% 0/2 [00:00<?, ?it/s]
Error executing job with overrides: []
Traceback (most recent call last):
  File "/content/drive/MyDrive/murata_labo_exp/murata_labo_exp_src/exp_1/main.py", line 239, in main
    trainer.fit(model, data_module)
  File "/usr/local/lib/python3.10/dist-packages/pytorch_lightning/trainer/trainer.py", line 520, in fit
    call._call_and_handle_interrupt(
  File "/usr/local/lib/python3.10/dist-packages/pytorch_lightning/trainer/call.py", line 44, in _call_and_handle_interrupt
    return trainer_fn(*args, **kwargs)
  File "/usr/local/lib/python3.10/dist-packages/pytorch_lightning/trainer/trainer.py", line 559, in _fit_impl
    self._run(model, ckpt_path=ckpt_path)
  File "/usr/local/lib/python3.10/dist-packages/pytorch_lightning/trainer/trainer.py", line 935, in _run
    results = self._run_stage()
  File "/usr/local/lib/python3.10/dist-packages/pytorch_lightning/trainer/trainer.py", line 976, in _run_stage
    self._run_sanity_check()
  File "/usr/local/lib/python3.10/dist-packages/pytorch_lightning/trainer/trainer.py", line 1005, in _run_sanity_check
    val_loop.run()
  File "/usr/local/lib/python3.10/dist-packages/pytorch_lightning/loops/utilities.py", line 177, in _decorator
    return loop_run(self, *args, **kwargs)
  File "/usr/local/lib/python3.10/dist-packages/pytorch_lightning/loops/evaluation_loop.py", line 122, in run
    return self.on_run_end()
  File "/usr/local/lib/python3.10/dist-packages/pytorch_lightning/loops/evaluation_loop.py", line 244, in on_run_end
    self._on_evaluation_epoch_end()
  File "/usr/local/lib/python3.10/dist-packages/pytorch_lightning/loops/evaluation_loop.py", line 326, in _on_evaluation_epoch_end
    call._call_lightning_module_hook(trainer, hook_name)
  File "/usr/local/lib/python3.10/dist-packages/pytorch_lightning/trainer/call.py", line 142, in _call_lightning_module_hook
    output = fn(*args, **kwargs)
  File "/content/drive/MyDrive/murata_labo_exp/murata_labo_exp_src/exp_1/main.py", line 163, in on_validation_epoch_end
    epoch_y_hats = torch.cat([x["batch_preds"] for x in outputs])
TypeError: 'bool' object is not iterable

Sanity Checking DataLoader 0: 100% 2/2 [00:01<00:00,  1.66it/s]