/usr/local/lib/python3.10/dist-packages/pytorch_lightning/loggers/wandb.py:389: There is a wandb run already in progress and newly created instances of `WandbLogger` will reuse this run. If this is not desired, call `wandb.finish()` before instantiating `WandbLogger`.
(…)sking/resolve/main/tokenizer_config.json: 100% 110/110 [00:00<00:00, 321kB/s]
(…)hole-word-masking/resolve/main/vocab.txt: 100% 15.7k/15.7k [00:00<00:00, 19.9MB/s]
(…)le-word-masking/resolve/main/config.json: 100% 478/478 [00:00<00:00, 891kB/s]

pytorch_model.bin: 100% 359M/359M [00:01<00:00, 194MB/s]
Error executing job with overrides: []
Traceback (most recent call last):
  File "/usr/local/lib/python3.10/dist-packages/torchmetrics/utilities/enums.py", line 45, in from_str
    me = super().from_str(value.replace("-", "_"), source=source)
  File "/usr/local/lib/python3.10/dist-packages/lightning_utilities/core/enums.py", line 54, in from_str
    raise ValueError(f"Invalid match: expected one of {cls._allowed_matches(source)}, but got {value}.")
ValueError: Invalid match: expected one of ['BINARY', 'MULTICLASS', 'MULTILABEL'], but got maltilabel.
The above exception was the direct cause of the following exception:
Traceback (most recent call last):
  File "/content/drive/MyDrive/murata_labo_exp/murata_labo_exp_src/exp4/main.py", line 409, in main
    model = MaltiLabelClassifierModel(
  File "/content/drive/MyDrive/murata_labo_exp/murata_labo_exp_src/exp4/main.py", line 159, in __init__
    torchmetrics.Accuracy(task="maltilabel", threshold=self.THRESHOLD),
  File "/usr/local/lib/python3.10/dist-packages/torchmetrics/classification/accuracy.py", line 493, in __new__
    task = ClassificationTask.from_str(task)
  File "/usr/local/lib/python3.10/dist-packages/torchmetrics/utilities/enums.py", line 48, in from_str
    raise ValueError(
ValueError: Invalid Classification: expected one of ['BINARY', 'MULTICLASS', 'MULTILABEL'], but got maltilabel.
Set the environment variable HYDRA_FULL_ERROR=1 for a complete stack trace.