/usr/local/lib/python3.10/dist-packages/pytorch_lightning/loggers/wandb.py:391: There is a wandb run already in progress and newly created instances of `WandbLogger` will reuse this run. If this is not desired, call `wandb.finish()` before instantiating `WandbLogger`.
[32m[I 2024-05-14 02:58:46,492][39m A new study created in memory with name: no-name-424c33a7-ab57-4a28-8f36-17addf2ebfa0
GPU available: True (cuda), used: True
TPU available: False, using: 0 TPU cores
IPU available: False, using: 0 IPUs
HPU available: False, using: 0 HPUs
You are using a CUDA device ('NVIDIA GeForce RTX 4090') that has Tensor Cores. To properly utilize them, you should set `torch.set_float32_matmul_precision('medium' | 'high')` which will trade-off precision for performance. For more details, read https://pytorch.org/docs/stable/generated/torch.set_float32_matmul_precision.html#torch.set_float32_matmul_precision
/usr/local/lib/python3.10/dist-packages/pytorch_lightning/callbacks/model_checkpoint.py:653: Checkpoint directory /content/murata_labo_exp/checkpoint exists and is not empty.
LOCAL_RANK: 0 - CUDA_VISIBLE_DEVICES: [0]
┏━━━━┳━━━━━━━━━━━━━━━━━━━━━━━━━━━━━┳━━━━━━━━━━━━━━━━━━┳━━━━━━━━┓
┃[1m    [22m┃[1m Name                        [22m┃[1m Type             [22m┃[1m Params [22m┃
┡━━━━╇━━━━━━━━━━━━━━━━━━━━━━━━━━━━━╇━━━━━━━━━━━━━━━━━━╇━━━━━━━━┩
│ 0  │ bert                        │ BertModel        │ 89.1 M │
│ 1  │ classifiers                 │ ModuleList       │  6.1 M │
│ 2  │ hidden_layer1               │ ModuleList       │  7.2 M │
│ 3  │ hidden_layer2               │ ModuleList       │ 14.4 K │
│ 4  │ sigmoid                     │ Sigmoid          │      0 │
│ 5  │ criterion                   │ BCELoss          │      0 │
│ 6  │ metrics                     │ MetricCollection │      0 │
│ 7  │ metrics_per_label_accuracy  │ MetricCollection │      0 │
│ 8  │ metrics_per_label_precision │ MetricCollection │      0 │
│ 9  │ metrics_per_label_recall    │ MetricCollection │      0 │
│ 10 │ metrics_per_label_f1score   │ MetricCollection │      0 │
└────┴─────────────────────────────┴──────────────────┴────────┘
[1mTrainable params[22m: 20.4 M
[1mNon-trainable params[22m: 82.0 M
[1mTotal params[22m: 102 M
[1mTotal estimated model params size (MB)[22m: 409
[37mSanity Checking[39m [35m━━━━━━━━━━━━━━━━━━━━━━━━━━━━━━━━━━━━━━━━[39m [37m2/2[39m [37m0:00:00 • 0:00:00[39m [37m81.59it/s
[?25h
[33m[W 2024-05-14 02:58:53,195][39m Trial 0 failed with parameters: {'batch_size': 54, 'epoch': 5, 'hidden_size': 497, 'hidden_size2': 901, 'chank_prev': 2} because of the following error: AttributeError("'MaltiLabelClassifierModel' object has no attribute 'validation_step_outputs_preds_return'").
Traceback (most recent call last):
  File "/usr/local/lib/python3.10/dist-packages/optuna/study/_optimize.py", line 196, in _run_trial
    value_or_values = func(trial)
  File "/content/murata_labo_exp/murata_labo_exp_src/exp9/main.py", line 597, in objective
    trainer.fit(model, data_module)
  File "/usr/local/lib/python3.10/dist-packages/pytorch_lightning/trainer/trainer.py", line 544, in fit
    call._call_and_handle_interrupt(
  File "/usr/local/lib/python3.10/dist-packages/pytorch_lightning/trainer/call.py", line 44, in _call_and_handle_interrupt
    return trainer_fn(*args, **kwargs)
  File "/usr/local/lib/python3.10/dist-packages/pytorch_lightning/trainer/trainer.py", line 580, in _fit_impl
    self._run(model, ckpt_path=ckpt_path)
  File "/usr/local/lib/python3.10/dist-packages/pytorch_lightning/trainer/trainer.py", line 987, in _run
    results = self._run_stage()
  File "/usr/local/lib/python3.10/dist-packages/pytorch_lightning/trainer/trainer.py", line 1031, in _run_stage
    self._run_sanity_check()
  File "/usr/local/lib/python3.10/dist-packages/pytorch_lightning/trainer/trainer.py", line 1060, in _run_sanity_check
    val_loop.run()
  File "/usr/local/lib/python3.10/dist-packages/pytorch_lightning/loops/utilities.py", line 182, in _decorator
    return loop_run(self, *args, **kwargs)
  File "/usr/local/lib/python3.10/dist-packages/pytorch_lightning/loops/evaluation_loop.py", line 142, in run
    return self.on_run_end()
  File "/usr/local/lib/python3.10/dist-packages/pytorch_lightning/loops/evaluation_loop.py", line 254, in on_run_end
    self._on_evaluation_epoch_end()
  File "/usr/local/lib/python3.10/dist-packages/pytorch_lightning/loops/evaluation_loop.py", line 334, in _on_evaluation_epoch_end
    call._call_lightning_module_hook(trainer, hook_name)
  File "/usr/local/lib/python3.10/dist-packages/pytorch_lightning/trainer/call.py", line 157, in _call_lightning_module_hook
    output = fn(*args, **kwargs)
  File "/content/murata_labo_exp/murata_labo_exp_src/exp9/main.py", line 380, in on_validation_epoch_end
    epoch_preds = torch.cat(self.validation_step_outputs_preds_return)
  File "/usr/local/lib/python3.10/dist-packages/torch/nn/modules/module.py", line 1688, in __getattr__
    raise AttributeError(f"'{type(self).__name__}' object has no attribute '{name}'")
AttributeError: 'MaltiLabelClassifierModel' object has no attribute 'validation_step_outputs_preds_return'
[33m[W 2024-05-14 02:58:53,197][39m Trial 0 failed with value None.
Error executing job with overrides: []
Traceback (most recent call last):
  File "/content/murata_labo_exp/murata_labo_exp_src/exp9/main.py", line 604, in main
    study.optimize(objective,n_trials=5)
  File "/usr/local/lib/python3.10/dist-packages/optuna/study/study.py", line 451, in optimize
    _optimize(
  File "/usr/local/lib/python3.10/dist-packages/optuna/study/_optimize.py", line 62, in _optimize
    _optimize_sequential(
  File "/usr/local/lib/python3.10/dist-packages/optuna/study/_optimize.py", line 159, in _optimize_sequential
    frozen_trial = _run_trial(study, func, catch)
  File "/usr/local/lib/python3.10/dist-packages/optuna/study/_optimize.py", line 247, in _run_trial
    raise func_err
  File "/usr/local/lib/python3.10/dist-packages/optuna/study/_optimize.py", line 196, in _run_trial
    value_or_values = func(trial)
  File "/content/murata_labo_exp/murata_labo_exp_src/exp9/main.py", line 597, in objective
    trainer.fit(model, data_module)
  File "/usr/local/lib/python3.10/dist-packages/pytorch_lightning/trainer/trainer.py", line 544, in fit
    call._call_and_handle_interrupt(
  File "/usr/local/lib/python3.10/dist-packages/pytorch_lightning/trainer/call.py", line 44, in _call_and_handle_interrupt
    return trainer_fn(*args, **kwargs)
  File "/usr/local/lib/python3.10/dist-packages/pytorch_lightning/trainer/trainer.py", line 580, in _fit_impl
    self._run(model, ckpt_path=ckpt_path)
  File "/usr/local/lib/python3.10/dist-packages/pytorch_lightning/trainer/trainer.py", line 987, in _run
    results = self._run_stage()
  File "/usr/local/lib/python3.10/dist-packages/pytorch_lightning/trainer/trainer.py", line 1031, in _run_stage
    self._run_sanity_check()
  File "/usr/local/lib/python3.10/dist-packages/pytorch_lightning/trainer/trainer.py", line 1060, in _run_sanity_check
    val_loop.run()
  File "/usr/local/lib/python3.10/dist-packages/pytorch_lightning/loops/utilities.py", line 182, in _decorator
    return loop_run(self, *args, **kwargs)
  File "/usr/local/lib/python3.10/dist-packages/pytorch_lightning/loops/evaluation_loop.py", line 142, in run
    return self.on_run_end()
  File "/usr/local/lib/python3.10/dist-packages/pytorch_lightning/loops/evaluation_loop.py", line 254, in on_run_end
    self._on_evaluation_epoch_end()
  File "/usr/local/lib/python3.10/dist-packages/pytorch_lightning/loops/evaluation_loop.py", line 334, in _on_evaluation_epoch_end
    call._call_lightning_module_hook(trainer, hook_name)
  File "/usr/local/lib/python3.10/dist-packages/pytorch_lightning/trainer/call.py", line 157, in _call_lightning_module_hook
    output = fn(*args, **kwargs)
  File "/content/murata_labo_exp/murata_labo_exp_src/exp9/main.py", line 380, in on_validation_epoch_end
    epoch_preds = torch.cat(self.validation_step_outputs_preds_return)
  File "/usr/local/lib/python3.10/dist-packages/torch/nn/modules/module.py", line 1688, in __getattr__
    raise AttributeError(f"'{type(self).__name__}' object has no attribute '{name}'")
AttributeError: 'MaltiLabelClassifierModel' object has no attribute 'validation_step_outputs_preds_return'
Set the environment variable HYDRA_FULL_ERROR=1 for a complete stack trace.