/usr/local/lib/python3.10/dist-packages/pytorch_lightning/loggers/wandb.py:396: UserWarning: There is a wandb run already in progress and newly created instances of `WandbLogger` will reuse this run. If this is not desired, call `wandb.finish()` before instantiating `WandbLogger`.
  rank_zero_warn(
Some weights of the model checkpoint at cl-tohoku/bert-base-japanese-char-whole-word-masking were not used when initializing BertModel: ['cls.predictions.transform.LayerNorm.bias', 'cls.predictions.bias', 'cls.predictions.decoder.weight', 'cls.seq_relationship.bias', 'cls.predictions.transform.LayerNorm.weight', 'cls.predictions.transform.dense.weight', 'cls.seq_relationship.weight', 'cls.predictions.transform.dense.bias']
- This IS expected if you are initializing BertModel from the checkpoint of a model trained on another task or with another architecture (e.g. initializing a BertForSequenceClassification model from a BertForPreTraining model).
- This IS NOT expected if you are initializing BertModel from the checkpoint of a model that you expect to be exactly identical (initializing a BertForSequenceClassification model from a BertForSequenceClassification model).
GPU available: False, used: False
TPU available: False, using: 0 TPU cores
IPU available: False, using: 0 IPUs
HPU available: False, using: 0 HPUs
  | Name         | Type      | Params
-------------------------------------------
0 | bert         | BertModel | 89.1 M
1 | hidden_layer | Linear    | 49.2 K
2 | layer        | Linear    | 65
3 | criterion    | BCELoss   | 0
-------------------------------------------
7.1 M     Trainable params
82.0 M    Non-trainable params
89.2 M    Total params
356.650   Total estimated model params size (MB)
Sanity Checking DataLoader 0:   0% 0/1 [00:00<?, ?it/s]
Error executing job with overrides: []
Traceback (most recent call last):
  File "/content/drive/MyDrive/murata_labo_exp/murata_labo_exp_src/exp3/main.py", line 375, in main
    trainer.fit(model, data_module)
  File "/usr/local/lib/python3.10/dist-packages/pytorch_lightning/trainer/trainer.py", line 529, in fit
    call._call_and_handle_interrupt(
  File "/usr/local/lib/python3.10/dist-packages/pytorch_lightning/trainer/call.py", line 42, in _call_and_handle_interrupt
    return trainer_fn(*args, **kwargs)
  File "/usr/local/lib/python3.10/dist-packages/pytorch_lightning/trainer/trainer.py", line 568, in _fit_impl
    self._run(model, ckpt_path=ckpt_path)
  File "/usr/local/lib/python3.10/dist-packages/pytorch_lightning/trainer/trainer.py", line 973, in _run
    results = self._run_stage()
  File "/usr/local/lib/python3.10/dist-packages/pytorch_lightning/trainer/trainer.py", line 1014, in _run_stage
    self._run_sanity_check()
  File "/usr/local/lib/python3.10/dist-packages/pytorch_lightning/trainer/trainer.py", line 1043, in _run_sanity_check
    val_loop.run()
  File "/usr/local/lib/python3.10/dist-packages/pytorch_lightning/loops/utilities.py", line 177, in _decorator
    return loop_run(self, *args, **kwargs)
  File "/usr/local/lib/python3.10/dist-packages/pytorch_lightning/loops/evaluation_loop.py", line 115, in run
    self._evaluation_step(batch, batch_idx, dataloader_idx)
  File "/usr/local/lib/python3.10/dist-packages/pytorch_lightning/loops/evaluation_loop.py", line 375, in _evaluation_step
    output = call._call_strategy_hook(trainer, hook_name, *step_kwargs.values())
  File "/usr/local/lib/python3.10/dist-packages/pytorch_lightning/trainer/call.py", line 291, in _call_strategy_hook
    output = fn(*args, **kwargs)
  File "/usr/local/lib/python3.10/dist-packages/pytorch_lightning/strategies/strategy.py", line 379, in validation_step
    return self.model.validation_step(*args, **kwargs)
  File "/content/drive/MyDrive/murata_labo_exp/murata_labo_exp_src/exp3/main.py", line 184, in validation_step
    loss, preds = self.forward(
  File "/content/drive/MyDrive/murata_labo_exp/murata_labo_exp_src/exp3/main.py", line 168, in forward
    loss = self.criterion(preds.view(-1), labels.long())
  File "/usr/local/lib/python3.10/dist-packages/torch/nn/modules/module.py", line 1501, in _call_impl
    return forward_call(*args, **kwargs)
  File "/usr/local/lib/python3.10/dist-packages/torch/nn/modules/loss.py", line 619, in forward
    return F.binary_cross_entropy(input, target, weight=self.weight, reduction=self.reduction)
  File "/usr/local/lib/python3.10/dist-packages/torch/nn/functional.py", line 3098, in binary_cross_entropy
    return torch._C._nn.binary_cross_entropy(input, target, weight, reduction_enum)
RuntimeError: Found dtype Long but expected Float
Sanity Checking DataLoader 0:   0% 0/1 [00:00<?, ?it/s]tensor([[0.5310],
        [0.5254],
        [0.5267],
        [0.5569],
        [0.5263],
        [0.5608],
        [0.5723],
        [0.5760],
        [0.5522],
        [0.5263],
        [0.5577],
        [0.5546],
        [0.5495],
        [0.5099],
        [0.5608],
        [0.5526],
        [0.5484],
        [0.5552],
        [0.5689],
        [0.5639],
        [0.5506]])
tensor([1, 0, 1, 1, 0, 1, 1, 1, 1, 1, 1, 1, 0, 0, 1, 0, 1, 1, 1, 1, 0])