
/usr/local/lib/python3.10/dist-packages/pytorch_lightning/loggers/wandb.py:396: There is a wandb run already in progress and newly created instances of `WandbLogger` will reuse this run. If this is not desired, call `wandb.finish()` before instantiating `WandbLogger`.
tokenizer_config.json: 100% 120/120 [00:00<00:00, 330kB/s]
vocab.txt: 100% 15.7k/15.7k [00:00<00:00, 29.9MB/s]
/usr/local/lib/python3.10/dist-packages/huggingface_hub/file_download.py:1132: FutureWarning: `resume_download` is deprecated and will be removed in version 1.0.0. Downloads always resume when possible. If you want to force a new download, use `force_download=True`.
  warnings.warn(
config.json: 100% 478/478 [00:00<00:00, 1.36MB/s]

pytorch_model.bin: 100% 359M/359M [00:01<00:00, 194MB/s]
GPU available: True (cuda), used: True
TPU available: False, using: 0 TPU cores
IPU available: False, using: 0 IPUs
HPU available: False, using: 0 HPUs
LOCAL_RANK: 0 - CUDA_VISIBLE_DEVICES: [0]
┏━━━┳━━━━━━━━━━━━━━━━━━━━━━━━━━━━━┳━━━━━━━━━━━━━━━━━━┳━━━━━━━━┓
┃[1m   [22m┃[1m Name                        [22m┃[1m Type             [22m┃[1m Params [22m┃
┡━━━╇━━━━━━━━━━━━━━━━━━━━━━━━━━━━━╇━━━━━━━━━━━━━━━━━━╇━━━━━━━━┩
│ 0 │ bert                        │ BertModel        │ 89.1 M │
│ 1 │ classifiers                 │ ModuleList       │  8.7 M │
│ 2 │ sigmoid                     │ Sigmoid          │      0 │
│ 3 │ criterion                   │ BCELoss          │      0 │
│ 4 │ metrics                     │ MetricCollection │      0 │
│ 5 │ metrics_per_label_accuracy  │ MetricCollection │      0 │
│ 6 │ metrics_per_label_precision │ MetricCollection │      0 │
│ 7 │ metrics_per_label_recall    │ MetricCollection │      0 │
│ 8 │ metrics_per_label_f1score   │ MetricCollection │      0 │
└───┴─────────────────────────────┴──────────────────┴────────┘
[1mTrainable params[22m: 15.8 M
[1mNon-trainable params[22m: 82.0 M
[1mTotal params[22m: 97.8 M
[1mTotal estimated model params size (MB)[22m: 391
[?25h
Error executing job with overrides: []
Traceback (most recent call last):
  File "/content/murata_labo_exp/murata_labo_exp_src/exp11/main.py", line 628, in main
    trainer.fit(model, data_module)
  File "/usr/local/lib/python3.10/dist-packages/pytorch_lightning/trainer/trainer.py", line 544, in fit
    call._call_and_handle_interrupt(
  File "/usr/local/lib/python3.10/dist-packages/pytorch_lightning/trainer/call.py", line 44, in _call_and_handle_interrupt
    return trainer_fn(*args, **kwargs)
  File "/usr/local/lib/python3.10/dist-packages/pytorch_lightning/trainer/trainer.py", line 580, in _fit_impl
    self._run(model, ckpt_path=ckpt_path)
  File "/usr/local/lib/python3.10/dist-packages/pytorch_lightning/trainer/trainer.py", line 987, in _run
    results = self._run_stage()
  File "/usr/local/lib/python3.10/dist-packages/pytorch_lightning/trainer/trainer.py", line 1031, in _run_stage
    self._run_sanity_check()
  File "/usr/local/lib/python3.10/dist-packages/pytorch_lightning/trainer/trainer.py", line 1060, in _run_sanity_check
    val_loop.run()
  File "/usr/local/lib/python3.10/dist-packages/pytorch_lightning/loops/utilities.py", line 182, in _decorator
    return loop_run(self, *args, **kwargs)
  File "/usr/local/lib/python3.10/dist-packages/pytorch_lightning/loops/evaluation_loop.py", line 128, in run
    batch, batch_idx, dataloader_idx = next(data_fetcher)
  File "/usr/local/lib/python3.10/dist-packages/pytorch_lightning/loops/fetchers.py", line 133, in __next__
    batch = super().__next__()
  File "/usr/local/lib/python3.10/dist-packages/pytorch_lightning/loops/fetchers.py", line 60, in __next__
    batch = next(self.iterator)
  File "/usr/local/lib/python3.10/dist-packages/pytorch_lightning/utilities/combined_loader.py", line 341, in __next__
    out = next(self._iterator)
  File "/usr/local/lib/python3.10/dist-packages/pytorch_lightning/utilities/combined_loader.py", line 142, in __next__
    out = next(self.iterators[0])
  File "/usr/local/lib/python3.10/dist-packages/torch/utils/data/dataloader.py", line 631, in __next__
    data = self._next_data()
  File "/usr/local/lib/python3.10/dist-packages/torch/utils/data/dataloader.py", line 1346, in _next_data
    return self._process_data(data)
  File "/usr/local/lib/python3.10/dist-packages/torch/utils/data/dataloader.py", line 1372, in _process_data
    data.reraise()
  File "/usr/local/lib/python3.10/dist-packages/torch/_utils.py", line 705, in reraise
    raise exception
KeyError: Caught KeyError in DataLoader worker process 0.
Original Traceback (most recent call last):
  File "/usr/local/lib/python3.10/dist-packages/pandas/core/indexes/base.py", line 3653, in get_loc
    return self._engine.get_loc(casted_key)
  File "pandas/_libs/index.pyx", line 147, in pandas._libs.index.IndexEngine.get_loc
  File "pandas/_libs/index.pyx", line 176, in pandas._libs.index.IndexEngine.get_loc
  File "pandas/_libs/hashtable_class_helper.pxi", line 7080, in pandas._libs.hashtable.PyObjectHashTable.get_item
  File "pandas/_libs/hashtable_class_helper.pxi", line 7088, in pandas._libs.hashtable.PyObjectHashTable.get_item
KeyError: 'flag'
The above exception was the direct cause of the following exception:
Traceback (most recent call last):
  File "/usr/local/lib/python3.10/dist-packages/torch/utils/data/_utils/worker.py", line 308, in _worker_loop
    data = fetcher.fetch(index)  # type: ignore[possibly-undefined]
  File "/usr/local/lib/python3.10/dist-packages/torch/utils/data/_utils/fetch.py", line 51, in fetch
    data = [self.dataset[idx] for idx in possibly_batched_index]
  File "/usr/local/lib/python3.10/dist-packages/torch/utils/data/_utils/fetch.py", line 51, in <listcomp>
    data = [self.dataset[idx] for idx in possibly_batched_index]
  File "/content/murata_labo_exp/murata_labo_exp_src/exp11/main.py", line 42, in __getitem__
    flags = data_row[self.FLAG_COLUMN]
  File "/usr/local/lib/python3.10/dist-packages/pandas/core/series.py", line 1007, in __getitem__
    return self._get_value(key)
  File "/usr/local/lib/python3.10/dist-packages/pandas/core/series.py", line 1116, in _get_value
    loc = self.index.get_loc(label)
  File "/usr/local/lib/python3.10/dist-packages/pandas/core/indexes/base.py", line 3655, in get_loc
    raise KeyError(key) from err
KeyError: 'flag'
Set the environment variable HYDRA_FULL_ERROR=1 for a complete stack trace.